<mujoco model="pendulum">
  <compiler angle="radian"/>

  <option timestep="0.002" iterations="1" ls_iterations="10"/>

  <worldbody>
    <geom name="floor" size="1 1 0.1" type="plane" rgba="0.9 0.9 0.9 1"/>
    <body name="pendulum_body" pos="0 0 0.5">
      <joint name="hinge" pos="0 0 0" axis="0 1 0" damping="0.0005" frictionloss="0.000001"/>
      <geom name="mass" size="0.01" rgba="1 0 0 1"/>
      <inertial pos="0 0 -0.1" mass="0.1" diaginertia="0.0001 0.0001 0.0001"/>
    </body>
  </worldbody>

  <actuator>
    <general name="torque" joint="hinge" ctrllimited="true" ctrlrange="-1 1"/>
  </actuator>
</mujoco>
